Workbook

Sheet TPT issue report
A1: Period: From Monday, 27-Oct-2025 06:00 AM To Monday, 03-Nov-2025 06:00 AM
A3: Region | B3: RT | C3: DT | D3: DM | E3: Site Name | F3: Sitecode | G3: Profile | H3: Game | I3: Credits | J3: Time play count | K3: Staff credit | L3: Card game count | M3: Total Plays | N3: Tickets | O3: TPT
A4: =IFERROR(VLOOKUP($F4,'Location List'!$A$2:$T$644,20,FALSE),"") -> Bill Eich | B4: =IFERROR(VLOOKUP($F4,'Location List'!$A$2:$T$644,19,FALSE),"") -> David Garcia | C4: =IFERROR(VLOOKUP($F4,'Location List'!$A$2:$T$644,18,FALSE),"") -> David Garibay Jr | D4: =IFERROR(VLOOKUP($F4,'Location List'!$A$2:$T$644,9,FALSE),"") -> ANTHONY CHAPA | E4: =IFERROR(VLOOKUP($F4,'Location List'!$A$2:$T$644,2,FALSE),"") -> TYLER | F4: 31 | G4: High Redemption | H4: BIG BASS LIL PRO | I4: 331 | J4: 723 | K4: 0 | L4: 17 | M4: 1054 | N4: 14552 | O4: 13.806 | BU4: =COUNTIFS($O$4:$O$6000,"<3") -> 2663 | BV4: low
A5: =IFERROR(VLOOKUP($F5,'Location List'!$A$2:$T$644,20,FALSE),"") -> Bill Eich | B5: =IFERROR(VLOOKUP($F5,'Location List'!$A$2:$T$644,19,FALSE),"") -> David Garcia | C5: =IFERROR(VLOOKUP($F5,'Location List'!$A$2:$T$644,18,FALSE),"") -> David Garibay Jr | D5: =IFERROR(VLOOKUP($F5,'Location List'!$A$2:$T$644,9,FALSE),"") -> ANTHONY CHAPA | E5: =IFERROR(VLOOKUP($F5,'Location List'!$A$2:$T$644,2,FALSE),"") -> TYLER | F5: 31 | G5: High Redemption | H5: FGTEEV OUT OF TIME | I5: 286 | J5: 373 | K5: 0 | L5: 16 | M5: 659 | N5: 4359 | O5: 6.615 | BU5: =COUNTIFS($O$4:$O$6000,">3") -> 1507 | BV5: high
A6: =IFERROR(VLOOKUP($F6,'Location List'!$A$2:$T$644,20,FALSE),"") -> Bill Eich | B6: =IFERROR(VLOOKUP($F6,'Location List'!$A$2:$T$644,19,FALSE),"") -> David Garcia | C6: =IFERROR(VLOOKUP($F6,'Location List'!$A$2:$T$644,18,FALSE),"") -> David Garibay Jr | D6: =IFERROR(VLOOKUP($F6,'Location List'!$A$2:$T$644,9,FALSE),"") -> ANTHONY CHAPA | E6: =IFERROR(VLOOKUP($F6,'Location List'!$A$2:$T$644,2,FALSE),"") -> TYLER | F6: 31 | G6: High Redemption | H6: SPONGEBOB JELLYFISH P1 | I6: 74 | J6: 72 | K6: 0 | L6: 19 | M6: 146 | N6: 2861 | O6: 19.596 | BU6: =SUM(BU4,BU5) -> 4170 | BV6: total
A7: =IFERROR(VLOOKUP($F7,'Location List'!$A$2:$T$644,20,FALSE),"") -> Bill Eich | B7: =IFERROR(VLOOKUP($F7,'Location List'!$A$2:$T$644,19,FALSE),"") -> David Garcia | C7: =IFERROR(VLOOKUP($F7,'Location List'!$A$2:$T$644,18,FALSE),"") -> David Garibay Jr | D7: =IFERROR(VLOOKUP($F7,'Location List'!$A$2:$T$644,9,FALSE),"") -> ANTHONY CHAPA | E7: =IFERROR(VLOOKUP($F7,'Location List'!$A$2:$T$644,2,FALSE),"") -> TYLER | F7: 31 | G7: Kiddie Skill | H7: DUO DRIVE P1 | I7: 138 | J7: 184 | K7: 0 | L7: 14 | M7: 322 | N7: 479 | O7: 1.488
A8: =IFERROR(VLOOKUP($F8,'Location List'!$A$2:$T$644,20,FALSE),"") -> Bill Eich | B8: =IFERROR(VLOOKUP($F8,'Location List'!$A$2:$T$644,19,FALSE),"") -> David Garcia | C8: =IFERROR(VLOOKUP($F8,'Location List'!$A$2:$T$644,18,FALSE),"") -> David Garibay Jr | D8: =IFERROR(VLOOKUP($F8,'Location List'!$A$2:$T$644,9,FALSE),"") -> ANTHONY CHAPA | E8: =IFERROR(VLOOKUP($F8,'Location List'!$A$2:$T$644,2,FALSE),"") -> TYLER | F8: 31 | G8: Skill | H8: PLANTS VS ZOMBIES | I8: 18 | J8: 16 | K8: 0 | L8: 21 | M8: 34 | N8: 237 | O8: 6.971
A9: =IFERROR(VLOOKUP($F9,'Location List'!$A$2:$T$644,20,FALSE),"") -> Bill Eich | B9: =IFERROR(VLOOKUP($F9,'Location List'!$A$2:$T$644,19,FALSE),"") -> David Garcia | C9: =IFERROR(VLOOKUP($F9,'Location List'!$A$2:$T$644,18,FALSE),"") -> David Garibay Jr | D9: =IFERROR(VLOOKUP($F9,'Location List'!$A$2:$T$644,9,FALSE),"") -> ANTHONY CHAPA | E9: =IFERROR(VLOOKUP($F9,'Location List'!$A$2:$T$644,2,FALSE),"") -> TYLER | F9: 31 | G9: Skill | H9: RAMPAGE P3 | I9: 58 | J9: 70 | K9: 0 | L9: 14 | M9: 128 | N9: 226 | O9: 1.766
A10: =IFERROR(VLOOKUP($F10,'Location List'!$A$2:$T$644,20,FALSE),"") -> Bill Eich | B10: =IFERROR(VLOOKUP($F10,'Location List'!$A$2:$T$644,19,FALSE),"") -> David Garcia | C10: =IFERROR(VLOOKUP($F10,'Location List'!$A$2:$T$644,18,FALSE),"") -> David Garibay Jr | D10: =IFERROR(VLOOKUP($F10,'Location List'!$A$2:$T$644,9,FALSE),"") -> ANTHONY CHAPA | E10: =IFERROR(VLOOKUP($F10,'Location List'!$A$2:$T$644,2,FALSE),"") -> TYLER | F10: 31 | G10: Skill | H10: ROBIN HOOD | I10: 82 | J10: 156 | K10: 0 | L10: 18 | M10: 238 | N10: 456 | O10: 1.916
A11: =IFERROR(VLOOKUP($F11,'Location List'!$A$2:$T$644,20,FALSE),"") -> Bill Eich | B11: =IFERROR(VLOOKUP($F11,'Location List'!$A$2:$T$644,19,FALSE),"") -> David Garcia | C11: =IFERROR(VLOOKUP($F11,'Location List'!$A$2:$T$644,18,FALSE),"") -> Hoang Dao | D11: =IFERROR(VLOOKUP($F11,'Location List'!$A$2:$T$644,9,FALSE),"") -> FRANK RAMIREZ | E11: =IFERROR(VLOOKUP($F11,'Location List'!$A$2:$T$644,2,FALSE),"") -> FM 1960 | F11: 32 | G11: Kiddie Skill | H11: CHAMELEON PARADIZE SINGLE | I11: 124 | J11: 72 | K11: 0 | L11: 19 | M11: 196 | N11: 3733 | O11: 19.046
A12: =IFERROR(VLOOKUP($F12,'Location List'!$A$2:$T$644,20,FALSE),"") -> Bill Eich | B12: =IFERROR(VLOOKUP($F12,'Location List'!$A$2:$T$644,19,FALSE),"") -> David Garcia | C12: =IFERROR(VLOOKUP($F12,'Location List'!$A$2:$T$644,18,FALSE),"") -> Hoang Dao | D12: =IFERROR(VLOOKUP($F12,'Location List'!$A$2:$T$644,9,FALSE),"") -> FRANK RAMIREZ | E12: =IFERROR(VLOOKUP($F12,'Location List'!$A$2:$T$644,2,FALSE),"") -> FM 1960 | F12: 32 | G12: Skill | H12: ALLEY CLASSIC P2 | I12: 239 | J12: 230 | K12: 0 | L12: 14 | M12: 469 | N12: 3090 | O12: 6.588
A13: =IFERROR(VLOOKUP($F13,'Location List'!$A$2:$T$644,20,FALSE),"") -> Bill Eich | B13: =IFERROR(VLOOKUP($F13,'Location List'!$A$2:$T$644,19,FALSE),"") -> David Garcia | C13: =IFERROR(VLOOKUP($F13,'Location List'!$A$2:$T$644,18,FALSE),"") -> Hoang Dao | D13: =IFERROR(VLOOKUP($F13,'Location List'!$A$2:$T$644,9,FALSE),"") -> FRANK RAMIREZ | E13: =IFERROR(VLOOKUP($F13,'Location List'!$A$2:$T$644,2,FALSE),"") -> FM 1960 | F13: 32 | G13: Skill | H13: BASEBALL PRO | I13: 186 | J13: 165 | K13: 0 | L13: 14 | M13: 351 | N13: 555 | O13: 1.581
A14: =IFERROR(VLOOKUP($F14,'Location List'!$A$2:$T$644,20,FALSE),"") -> Bill Eich | B14: =IFERROR(VLOOKUP($F14,'Location List'!$A$2:$T$644,19,FALSE),"") -> David Garcia | C14: =IFERROR(VLOOKUP($F14,'Location List'!$A$2:$T$644,18,FALSE),"") -> Hoang Dao | D14: =IFERROR(VLOOKUP($F14,'Location List'!$A$2:$T$644,9,FALSE),"") -> FRANK RAMIREZ | E14: =IFERROR(VLOOKUP($F14,'Location List'!$A$2:$T$644,2,FALSE),"") -> COPPERFIELD | F14: 33 | G14: Kiddie Skill | H14: BUNNY POND | I14: 189 | J14: 310 | K14: 0 | L14: 15 | M14: 499 | N14: 505 | O14: 1.012
A15: =IFERROR(VLOOKUP($F15,'Location List'!$A$2:$T$644,20,FALSE),"") -> Bill Eich | B15: =IFERROR(VLOOKUP($F15,'Location List'!$A$2:$T$644,19,FALSE),"") -> David Garcia | C15: =IFERROR(VLOOKUP($F15,'Location List'!$A$2:$T$644,18,FALSE),"") -> Hoang Dao | D15: =IFERROR(VLOOKUP($F15,'Location List'!$A$2:$T$644,9,FALSE),"") -> FRANK RAMIREZ | E15: =IFERROR(VLOOKUP($F15,'Location List'!$A$2:$T$644,2,FALSE),"") -> COPPERFIELD | F15: 33 | G15: Skill | H15: DICEY JUMP | I15: 167 | J15: 168 | K15: 0 | L15: 14 | M15: 335 | N15: 660 | O15: 1.97
A16: =IFERROR(VLOOKUP($F16,'Location List'!$A$2:$T$644,20,FALSE),"") -> Bill Eich | B16: =IFERROR(VLOOKUP($F16,'Location List'!$A$2:$T$644,19,FALSE),"") -> David Garcia | C16: =IFERROR(VLOOKUP($F16,'Location List'!$A$2:$T$644,18,FALSE),"") -> Hoang Dao | D16: =IFERROR(VLOOKUP($F16,'Location List'!$A$2:$T$644,9,FALSE),"") -> FRANK RAMIREZ | E16: =IFERROR(VLOOKUP($F16,'Location List'!$A$2:$T$644,2,FALSE),"") -> COPPERFIELD | F16: 33 | G16: Skill | H16: TROLLS P2 | I16: 356 | J16: 281 | K16: 0 | L16: 17 | M16: 637 | N16: 6158 | O16: 9.667
A17: =IFERROR(VLOOKUP($F17,'Location List'!$A$2:$T$644,20,FALSE),"") -> Bill Eich | B17: =IFERROR(VLOOKUP($F17,'Location List'!$A$2:$T$644,19,FALSE),"") -> David Garcia | C17: =IFERROR(VLOOKUP($F17,'Location List'!$A$2:$T$644,18,FALSE),"") -> Hoang Dao | D17: =IFERROR(VLOOKUP($F17,'Location List'!$A$2:$T$644,9,FALSE),"") -> FRANK RAMIREZ | E17: =IFERROR(VLOOKUP($F17,'Location List'!$A$2:$T$644,2,FALSE),"") -> COPPERFIELD | F17: 33 | G17: Skill | H17: TROLLS P4 | I17: 191 | J17: 261 | K17: 0 | L17: 16 | M17: 452 | N17: 518 | O17: 1.146
A18: =IFERROR(VLOOKUP($F18,'Location List'!$A$2:$T$644,20,FALSE),"") -> Bill Eich | B18: =IFERROR(VLOOKUP($F18,'Location List'!$A$2:$T$644,19,FALSE),"") -> David Garcia | C18: =IFERROR(VLOOKUP($F18,'Location List'!$A$2:$T$644,18,FALSE),"") -> Mike Kralick | D18: =IFERROR(VLOOKUP($F18,'Location List'!$A$2:$T$644,9,FALSE),"") -> KELLI KASPER | E18: =IFERROR(VLOOKUP($F18,'Location List'!$A$2:$T$644,2,FALSE),"") -> LEWISVILLE | F18: 35 | G18: Skill | H18: ALLEY CLASSIC P2 | I18: 195 | J18: 207 | K18: 0 | L18: 17 | M18: 402 | N18: 2937 | O18: 7.306
... A4173: =IFERROR(VLOOKUP($F4173,'Location List'!$A$2:$T$644,20,FALSE),"") -> Chris Kelly | B4173: =IFERROR(VLOOKUP($F4173,'Location List'!$A$2:$T$644,19,FALSE),"") -> Chris Parenti | C4173: =IFERROR(VLOOKUP($F4173,'Location List'!$A$2:$T$644,18,FALSE),"") -> Robert Lane | D4173: =IFERROR(VLOOKUP($F4173,'Location List'!$A$2:$T$644,9,FALSE),"") -> SUSAN JENSEN | E4173: =IFERROR(VLOOKUP($F4173,'Location List'!$A$2:$T$644,2,FALSE),"") -> ROANOKE | F4173: 972 | G4173: Skill | H4173: DEAL NO DEAL | I4173: 261 | J4173: 190 | K4173: 0 | L4173: 21 | M4173: 451 | N4173: 2948 | O4173: 6.537
A4174: =IFERROR(VLOOKUP($F4174,'Location List'!$A$2:$T$644,20,FALSE),"") | B4174: =IFERROR(VLOOKUP($F4174,'Location List'!$A$2:$T$644,19,FALSE),"") | C4174: =IFERROR(VLOOKUP($F4174,'Location List'!$A$2:$T$644,18,FALSE),"") | D4174: =IFERROR(VLOOKUP($F4174,'Location List'!$A$2:$T$644,9,FALSE),"") | E4174: =IFERROR(VLOOKUP($F4174,'Location List'!$A$2:$T$644,2,FALSE),"")
A4175: =IFERROR(VLOOKUP($F4175,'Location List'!$A$2:$T$644,20,FALSE),"") | B4175: =IFERROR(VLOOKUP($F4175,'Location List'!$A$2:$T$644,19,FALSE),"") | C4175: =IFERROR(VLOOKUP($F4175,'Location List'!$A$2:$T$644,18,FALSE),"") | D4175: =IFERROR(VLOOKUP($F4175,'Location List'!$A$2:$T$644,9,FALSE),"") | E4175: =IFERROR(VLOOKUP($F4175,'Location List'!$A$2:$T$644,2,FALSE),"")
A4176: =IFERROR(VLOOKUP($F4176,'Location List'!$A$2:$T$644,20,FALSE),"") | B4176: =IFERROR(VLOOKUP($F4176,'Location List'!$A$2:$T$644,19,FALSE),"") | C4176: =IFERROR(VLOOKUP($F4176,'Location List'!$A$2:$T$644,18,FALSE),"") | D4176: =IFERROR(VLOOKUP($F4176,'Location List'!$A$2:$T$644,9,FALSE),"") | E4176: =IFERROR(VLOOKUP($F4176,'Location List'!$A$2:$T$644,2,FALSE),"")
A4177: =IFERROR(VLOOKUP($F4177,'Location List'!$A$2:$T$644,20,FALSE),"") | B4177: =IFERROR(VLOOKUP($F4177,'Location List'!$A$2:$T$644,19,FALSE),"") | C4177: =IFERROR(VLOOKUP($F4177,'Location List'!$A$2:$T$644,18,FALSE),"") | D4177: =IFERROR(VLOOKUP($F4177,'Location List'!$A$2:$T$644,9,FALSE),"") | E4177: =IFERROR(VLOOKUP($F4177,'Location List'!$A$2:$T$644,2,FALSE),"")
A4178: =IFERROR(VLOOKUP($F4178,'Location List'!$A$2:$T$644,20,FALSE),"") | B4178: =IFERROR(VLOOKUP($F4178,'Location List'!$A$2:$T$644,19,FALSE),"") | C4178: =IFERROR(VLOOKUP($F4178,'Location List'!$A$2:$T$644,18,FALSE),"") | D4178: =IFERROR(VLOOKUP($F4178,'Location List'!$A$2:$T$644,9,FALSE),"") | E4178: =IFERROR(VLOOKUP($F4178,'Location List'!$A$2:$T$644,2,FALSE),"")
A4179: =IFERROR(VLOOKUP($F4179,'Location List'!$A$2:$T$644,20,FALSE),"") | B4179: =IFERROR(VLOOKUP($F4179,'Location List'!$A$2:$T$644,19,FALSE),"") | C4179: =IFERROR(VLOOKUP($F4179,'Location List'!$A$2:$T$644,18,FALSE),"") | D4179: =IFERROR(VLOOKUP($F4179,'Location List'!$A$2:$T$644,9,FALSE),"") | E4179: =IFERROR(VLOOKUP($F4179,'Location List'!$A$2:$T$644,2,FALSE),"")
A4180: =IFERROR(VLOOKUP($F4180,'Location List'!$A$2:$T$644,20,FALSE),"") | B4180: =IFERROR(VLOOKUP($F4180,'Location List'!$A$2:$T$644,19,FALSE),"") | C4180: =IFERROR(VLOOKUP($F4180,'Location List'!$A$2:$T$644,18,FALSE),"") | D4180: =IFERROR(VLOOKUP($F4180,'Location List'!$A$2:$T$644,9,FALSE),"") | E4180: =IFERROR(VLOOKUP($F4180,'Location List'!$A$2:$T$644,2,FALSE),"")
A4181: =IFERROR(VLOOKUP($F4181,'Location List'!$A$2:$T$644,20,FALSE),"") | B4181: =IFERROR(VLOOKUP($F4181,'Location List'!$A$2:$T$644,19,FALSE),"") | C4181: =IFERROR(VLOOKUP($F4181,'Location List'!$A$2:$T$644,18,FALSE),"") | D4181: =IFERROR(VLOOKUP($F4181,'Location List'!$A$2:$T$644,9,FALSE),"") | E4181: =IFERROR(VLOOKUP($F4181,'Location List'!$A$2:$T$644,2,FALSE),"")
A4182: =IFERROR(VLOOKUP($F4182,'Location List'!$A$2:$T$644,20,FALSE),"") | B4182: =IFERROR(VLOOKUP($F4182,'Location List'!$A$2:$T$644,19,FALSE),"") | C4182: =IFERROR(VLOOKUP($F4182,'Location List'!$A$2:$T$644,18,FALSE),"") | D4182: =IFERROR(VLOOKUP($F4182,'Location List'!$A$2:$T$644,9,FALSE),"") | E4182: =IFERROR(VLOOKUP($F4182,'Location List'!$A$2:$T$644,2,FALSE),"")
A4183: =IFERROR(VLOOKUP($F4183,'Location List'!$A$2:$T$644,20,FALSE),"") | B4183: =IFERROR(VLOOKUP($F4183,'Location List'!$A$2:$T$644,19,FALSE),"") | C4183: =IFERROR(VLOOKUP($F4183,'Location List'!$A$2:$T$644,18,FALSE),"") | D4183: =IFERROR(VLOOKUP($F4183,'Location List'!$A$2:$T$644,9,FALSE),"") | E4183: =IFERROR(VLOOKUP($F4183,'Location List'!$A$2:$T$644,2,FALSE),"")
A4184: =IFERROR(VLOOKUP($F4184,'Location List'!$A$2:$T$644,20,FALSE),"") | B4184: =IFERROR(VLOOKUP($F4184,'Location List'!$A$2:$T$644,19,FALSE),"") | C4184: =IFERROR(VLOOKUP($F4184,'Location List'!$A$2:$T$644,18,FALSE),"") | D4184: =IFERROR(VLOOKUP($F4184,'Location List'!$A$2:$T$644,9,FALSE),"") | E4184: =IFERROR(VLOOKUP($F4184,'Location List'!$A$2:$T$644,2,FALSE),"")
A4185: =IFERROR(VLOOKUP($F4185,'Location List'!$A$2:$T$644,20,FALSE),"") | B4185: =IFERROR(VLOOKUP($F4185,'Location List'!$A$2:$T$644,19,FALSE),"") | C4185: =IFERROR(VLOOKUP($F4185,'Location List'!$A$2:$T$644,18,FALSE),"") | D4185: =IFERROR(VLOOKUP($F4185,'Location List'!$A$2:$T$644,9,FALSE),"") | E4185: =IFERROR(VLOOKUP($F4185,'Location List'!$A$2:$T$644,2,FALSE),"")
... A6000: =IFERROR(VLOOKUP($F6000,'Location List'!$A$2:$T$644,20,FALSE),"") | B6000: =IFERROR(VLOOKUP($F6000,'Location List'!$A$2:$T$644,19,FALSE),"") | C6000: =IFERROR(VLOOKUP($F6000,'Location List'!$A$2:$T$644,18,FALSE),"") | D6000: =IFERROR(VLOOKUP($F6000,'Location List'!$A$2:$T$644,9,FALSE),"") | E6000: =IFERROR(VLOOKUP($F6000,'Location List'!$A$2:$T$644,2,FALSE),"")
A6991: =IFERROR(VLOOKUP($F6991,'Location List'!$A$2:$QR$463,20,FALSE),"") | B6991: =IFERROR(VLOOKUP($F6991,'Location List'!$A$2:$QR$463,19,FALSE),"") | C6991: =IFERROR(VLOOKUP($F6991,'Location List'!$A$2:$QR$463,18,FALSE),"") | D6991: =IFERROR(VLOOKUP($F6991,'Location List'!$A$2:$QR$463,9,FALSE),"") | E6991: =IFERROR(VLOOKUP($F6991,'Location List'!$A$2:$QR$463,2,FALSE),"")
A6992: =IFERROR(VLOOKUP($F6992,'Location List'!$A$2:$QR$463,20,FALSE),"") | B6992: =IFERROR(VLOOKUP($F6992,'Location List'!$A$2:$QR$463,19,FALSE),"") | C6992: =IFERROR(VLOOKUP($F6992,'Location List'!$A$2:$QR$463,18,FALSE),"") | D6992: =IFERROR(VLOOKUP($F6992,'Location List'!$A$2:$QR$463,9,FALSE),"") | E6992: =IFERROR(VLOOKUP($F6992,'Location List'!$A$2:$QR$463,2,FALSE),"")
A6993: =IFERROR(VLOOKUP($F6993,'Location List'!$A$2:$QR$463,20,FALSE),"") | B6993: =IFERROR(VLOOKUP($F6993,'Location List'!$A$2:$QR$463,19,FALSE),"") | C6993: =IFERROR(VLOOKUP($F6993,'Location List'!$A$2:$QR$463,18,FALSE),"") | D6993: =IFERROR(VLOOKUP($F6993,'Location List'!$A$2:$QR$463,9,FALSE),"") | E6993: =IFERROR(VLOOKUP($F6993,'Location List'!$A$2:$QR$463,2,FALSE),"")
A6994: =IFERROR(VLOOKUP($F6994,'Location List'!$A$2:$QR$463,20,FALSE),"") | B6994: =IFERROR(VLOOKUP($F6994,'Location List'!$A$2:$QR$463,19,FALSE),"") | C6994: =IFERROR(VLOOKUP($F6994,'Location List'!$A$2:$QR$463,18,FALSE),"") | D6994: =IFERROR(VLOOKUP($F6994,'Location List'!$A$2:$QR$463,9,FALSE),"") | E6994: =IFERROR(VLOOKUP($F6994,'Location List'!$A$2:$QR$463,2,FALSE),"")
A6995: =IFERROR(VLOOKUP($F6995,'Location List'!$A$2:$QR$463,20,FALSE),"") | B6995: =IFERROR(VLOOKUP($F6995,'Location List'!$A$2:$QR$463,19,FALSE),"") | C6995: =IFERROR(VLOOKUP($F6995,'Location List'!$A$2:$QR$463,18,FALSE),"") | D6995: =IFERROR(VLOOKUP($F6995,'Location List'!$A$2:$QR$463,9,FALSE),"") | E6995: =IFERROR(VLOOKUP($F6995,'Location List'!$A$2:$QR$463,2,FALSE),"")
A6996: =IFERROR(VLOOKUP($F6996,'Location List'!$A$2:$QR$463,20,FALSE),"") | B6996: =IFERROR(VLOOKUP($F6996,'Location List'!$A$2:$QR$463,19,FALSE),"") | C6996: =IFERROR(VLOOKUP($F6996,'Location List'!$A$2:$QR$463,18,FALSE),"") | D6996: =IFERROR(VLOOKUP($F6996,'Location List'!$A$2:$QR$463,9,FALSE),"") | E6996: =IFERROR(VLOOKUP($F6996,'Location List'!$A$2:$QR$463,2,FALSE),"")
A6997: =IFERROR(VLOOKUP($F6997,'Location List'!$A$2:$QR$463,20,FALSE),"") | B6997: =IFERROR(VLOOKUP($F6997,'Location List'!$A$2:$QR$463,19,FALSE),"") | C6997: =IFERROR(VLOOKUP($F6997,'Location List'!$A$2:$QR$463,18,FALSE),"") | D6997: =IFERROR(VLOOKUP($F6997,'Location List'!$A$2:$QR$463,9,FALSE),"") | E6997: =IFERROR(VLOOKUP($F6997,'Location List'!$A$2:$QR$463,2,FALSE),"")
A6998: =IFERROR(VLOOKUP($F6998,'Location List'!$A$2:$QR$463,20,FALSE),"") | B6998: =IFERROR(VLOOKUP($F6998,'Location List'!$A$2:$QR$463,19,FALSE),"") | C6998: =IFERROR(VLOOKUP($F6998,'Location List'!$A$2:$QR$463,18,FALSE),"") | D6998: =IFERROR(VLOOKUP($F6998,'Location List'!$A$2:$QR$463,9,FALSE),"") | E6998: =IFERROR(VLOOKUP($F6998,'Location List'!$A$2:$QR$463,2,FALSE),"")
A6999: =IFERROR(VLOOKUP($F6999,'Location List'!$A$2:$QR$463,20,FALSE),"") | B6999: =IFERROR(VLOOKUP($F6999,'Location List'!$A$2:$QR$463,19,FALSE),"") | C6999: =IFERROR(VLOOKUP($F6999,'Location List'!$A$2:$QR$463,18,FALSE),"") | D6999: =IFERROR(VLOOKUP($F6999,'Location List'!$A$2:$QR$463,9,FALSE),"") | E6999: =IFERROR(VLOOKUP($F6999,'Location List'!$A$2:$QR$463,2,FALSE),"")
...

Sheet Average TPT Report
A1: ='TPT issue report'!A1 -> Period: From Monday, 27-Oct-2025 06:00 AM To Monday, 03-Nov-2025 06:00 AM
A2: Region | B2: RT | C2: DT | D2: DM | E2: Site name | F2: Site Code | G2: Credits | H2: Total Amount | I2: Card game count | J2: Total Plays | K2: Tickets | L2: AVG TPT
A3: =IFERROR(VLOOKUP(F3,'Location List'!$A$2:$QR$463,20,FALSE),"") -> Bill Eich | B3: =IFERROR(VLOOKUP(F3,'Location List'!$A$2:$QR$644,19,FALSE),"") -> David Garcia | C3: =IFERROR(VLOOKUP(F3,'Location List'!$A$2:$QR$644,18,FALSE),"") -> David Garibay Jr | D3: =IFERROR(VLOOKUP(F3,'Location List'!$A$2:$QR$644,9,FALSE),"") -> ANTHONY CHAPA | E3: =IFERROR(VLOOKUP(F3,'Location List'!$A$2:$QR$644,2,FALSE),"") -> TYLER | F3: 31 | G3: 18595 | H3: 44198 | I3: 1332 | J3: 42866 | K3: 140329 | L3: 3.27
A4: =IFERROR(VLOOKUP(F4,'Location List'!$A$2:$QR$463,20,FALSE),"") -> Bill Eich | B4: =IFERROR(VLOOKUP(F4,'Location List'!$A$2:$QR$644,19,FALSE),"") -> David Garcia | C4: =IFERROR(VLOOKUP(F4,'Location List'!$A$2:$QR$644,18,FALSE),"") -> Hoang Dao | D4: =IFERROR(VLOOKUP(F4,'Location List'!$A$2:$QR$644,9,FALSE),"") -> FRANK RAMIREZ | E4: =IFERROR(VLOOKUP(F4,'Location List'!$A$2:$QR$644,2,FALSE),"") -> FM 1960 | F4: 32 | G4: 17861 | H4: 32276 | I4: 1408 | J4: 30868 | K4: 90022 | L4: 2.92
A5: =IFERROR(VLOOKUP(F5,'Location List'!$A$2:$QR$463,20,FALSE),"") -> Bill Eich | B5: =IFERROR(VLOOKUP(F5,'Location List'!$A$2:$QR$644,19,FALSE),"") -> David Garcia | C5: =IFERROR(VLOOKUP(F5,'Location List'!$A$2:$QR$644,18,FALSE),"") -> Hoang Dao | D5: =IFERROR(VLOOKUP(F5,'Location List'!$A$2:$QR$644,9,FALSE),"") -> FRANK RAMIREZ | E5: =IFERROR(VLOOKUP(F5,'Location List'!$A$2:$QR$644,2,FALSE),"") -> COPPERFIELD | F5: 33 | G5: 14750 | H5: 34441 | I5: 1071 | J5: 33370 | K5: 95513 | L5: 2.86
A6: =IFERROR(VLOOKUP(F6,'Location List'!$A$2:$QR$463,20,FALSE),"") -> Bill Eich | B6: =IFERROR(VLOOKUP(F6,'Location List'!$A$2:$QR$644,19,FALSE),"") -> David Garcia | C6: =IFERROR(VLOOKUP(F6,'Location List'!$A$2:$QR$644,18,FALSE),"") -> Mike Kralick | D6: =IFERROR(VLOOKUP(F6,'Location List'!$A$2:$QR$644,9,FALSE),"") -> KELLI KASPER | E6: =IFERROR(VLOOKUP(F6,'Location List'!$A$2:$QR$644,2,FALSE),"") -> LEWISVILLE | F6: 35 | G6: 10448 | H6: 21741 | I6: 946 | J6: 20795 | K6: 65760 | L6: 3.16
A7: =IFERROR(VLOOKUP(F7,'Location List'!$A$2:$QR$463,20,FALSE),"") -> Bill Eich | B7: =IFERROR(VLOOKUP(F7,'Location List'!$A$2:$QR$644,19,FALSE),"") -> David Garcia | C7: =IFERROR(VLOOKUP(F7,'Location List'!$A$2:$QR$644,18,FALSE),"") -> Jose Sandoval | D7: =IFERROR(VLOOKUP(F7,'Location List'!$A$2:$QR$644,9,FALSE),"") -> ERIC BARGAS | E7: =IFERROR(VLOOKUP(F7,'Location List'!$A$2:$QR$644,2,FALSE),"") -> ROCKWALL | F7: 38 | G7: 16162 | H7: 34810 | I7: 2072 | J7: 32738 | K7: 100204 | L7: 3.06
A8: =IFERROR(VLOOKUP(F8,'Location List'!$A$2:$QR$463,20,FALSE),"") -> Bill Eich | B8: =IFERROR(VLOOKUP(F8,'Location List'!$A$2:$QR$644,19,FALSE),"") -> Dennis Morgan | C8: =IFERROR(VLOOKUP(F8,'Location List'!$A$2:$QR$644,18,FALSE),"") -> Wayne Rough | D8: =IFERROR(VLOOKUP(F8,'Location List'!$A$2:$QR$644,9,FALSE),"") -> HASHEM SAADAT | E8: =IFERROR(VLOOKUP(F8,'Location List'!$A$2:$QR$644,2,FALSE),"") -> ALBEMARLE | F8: 39 | G8: 8929 | H8: 21655 | I8: 1237 | J8: 20418 | K8: 61663 | L8: 3.02
A9: =IFERROR(VLOOKUP(F9,'Location List'!$A$2:$QR$463,20,FALSE),"") -> Tim Kerum | B9: =IFERROR(VLOOKUP(F9,'Location List'!$A$2:$QR$644,19,FALSE),"") -> Troy Chaney | C9: =IFERROR(VLOOKUP(F9,'Location List'!$A$2:$QR$644,18,FALSE),"") -> Manuel Lopez | D9: =IFERROR(VLOOKUP(F9,'Location List'!$A$2:$QR$644,9,FALSE),"") -> OCTAVIO CASTANEDA | E9: =IFERROR(VLOOKUP(F9,'Location List'!$A$2:$QR$644,2,FALSE),"") -> BAKERSFIELD | F9: 41 | G9: 26319 | H9: 49029 | I9: 1280 | J9: 47749 | K9: 140866 | L9: 2.95
A10: =IFERROR(VLOOKUP(F10,'Location List'!$A$2:$QR$463,20,FALSE),"") -> Tim Kerum | B10: =IFERROR(VLOOKUP(F10,'Location List'!$A$2:$QR$644,19,FALSE),"") -> Troy Chaney | C10: =IFERROR(VLOOKUP(F10,'Location List'!$A$2:$QR$644,18,FALSE),"") -> Albino Ramirez | D10: =IFERROR(VLOOKUP(F10,'Location List'!$A$2:$QR$644,9,FALSE),"") -> Adam Shafran | E10: =IFERROR(VLOOKUP(F10,'Location List'!$A$2:$QR$644,2,FALSE),"") -> FRESNO | F10: 42 | G10: 17773 | H10: 34731 | I10: 1155 | J10: 33576 | K10: 95836 | L10: 2.85
A11: =IFERROR(VLOOKUP(F11,'Location List'!$A$2:$QR$463,20,FALSE),"") -> Tim Kerum | B11: =IFERROR(VLOOKUP(F11,'Location List'!$A$2:$QR$644,19,FALSE),"") -> Troy Chaney | C11: =IFERROR(VLOOKUP(F11,'Location List'!$A$2:$QR$644,18,FALSE),"") -> Manuel Lopez | D11: =IFERROR(VLOOKUP(F11,'Location List'!$A$2:$QR$644,9,FALSE),"") -> OCTAVIO CASTANEDA | E11: =IFERROR(VLOOKUP(F11,'Location List'!$A$2:$QR$644,2,FALSE),"") -> VISALIA | F11: 43 | G11: 25512 | H11: 53359 | I11: 1356 | J11: 52003 | K11: 154161 | L11: 2.96
A12: =IFERROR(VLOOKUP(F12,'Location List'!$A$2:$QR$463,20,FALSE),"") -> Tim Kerum | B12: =IFERROR(VLOOKUP(F12,'Location List'!$A$2:$QR$644,19,FALSE),"") -> Troy Chaney | C12: =IFERROR(VLOOKUP(F12,'Location List'!$A$2:$QR$644,18,FALSE),"") | D12: =IFERROR(VLOOKUP(F12,'Location List'!$A$2:$QR$644,9,FALSE),"") -> PATTY CEDILLO | E12: =IFERROR(VLOOKUP(F12,'Location List'!$A$2:$QR$644,2,FALSE),"") -> OCEANSIDE | F12: 45 | G12: 21324 | H12: 37705 | I12: 1162 | J12: 36543 | K12: 110446 | L12: 3.02
A13: =IFERROR(VLOOKUP(F13,'Location List'!$A$2:$QR$463,20,FALSE),"") -> Chris Kelly | B13: =IFERROR(VLOOKUP(F13,'Location List'!$A$2:$QR$644,19,FALSE),"") -> Mike Seymour | C13: =IFERROR(VLOOKUP(F13,'Location List'!$A$2:$QR$644,18,FALSE),"") -> James Schwab | D13: =IFERROR(VLOOKUP(F13,'Location List'!$A$2:$QR$644,9,FALSE),"") -> REGINALD DAVENPORT | E13: =IFERROR(VLOOKUP(F13,'Location List'!$A$2:$QR$644,2,FALSE),"") -> SPRINGFIELD (IL) | F13: 47 | G13: 11117 | H13: 26383 | I13: 1214 | J13: 25169 | K13: 79065 | L13: 3.14
A14: =IFERROR(VLOOKUP(F14,'Location List'!$A$2:$QR$463,20,FALSE),"") -> Bill Eich | B14: =IFERROR(VLOOKUP(F14,'Location List'!$A$2:$QR$644,19,FALSE),"") -> Dennis Morgan | C14: =IFERROR(VLOOKUP(F14,'Location List'!$A$2:$QR$644,18,FALSE),"") -> Richard Boykin | D14: =IFERROR(VLOOKUP(F14,'Location List'!$A$2:$QR$644,9,FALSE),"") -> BRIAN PITRE | E14: =IFERROR(VLOOKUP(F14,'Location List'!$A$2:$QR$644,2,FALSE),"") -> ALEXANDRIA | F14: 48 | G14: 11607 | H14: 24238 | I14: 1068 | J14: 23170 | K14: 67493 | L14: 2.91
... A462: =IFERROR(VLOOKUP(F462,'Location List'!$A$2:$QR$463,20,FALSE),"") -> Chris Kelly | B462: =IFERROR(VLOOKUP(F462,'Location List'!$A$2:$QR$644,19,FALSE),"") -> Chris Parenti | C462: =IFERROR(VLOOKUP(F462,'Location List'!$A$2:$QR$644,18,FALSE),"") -> Robert Lane | D462: =IFERROR(VLOOKUP(F462,'Location List'!$A$2:$QR$644,9,FALSE),"") -> SUSAN JENSEN | E462: =IFERROR(VLOOKUP(F462,'Location List'!$A$2:$QR$644,2,FALSE),"") -> ROANOKE | F462: 972 | G462: 20097 | H462: 47000 | I462: 1405 | J462: 45595 | K462: 128907 | L462: 2.83
A463: =IFERROR(VLOOKUP(F463,'Location List'!$A$2:$QR$463,20,FALSE),"") | B463: =IFERROR(VLOOKUP(F463,'Location List'!$A$2:$QR$644,19,FALSE),"") | C463: =IFERROR(VLOOKUP(F463,'Location List'!$A$2:$QR$644,18,FALSE),"") | D463: =IFERROR(VLOOKUP(F463,'Location List'!$A$2:$QR$644,9,FALSE),"") | E463: =IFERROR(VLOOKUP(F463,'Location List'!$A$2:$QR$644,2,FALSE),"")
A464: =IFERROR(VLOOKUP(F464,'Location List'!$A$2:$QR$463,20,FALSE),"") | B464: =IFERROR(VLOOKUP(F464,'Location List'!$A$2:$QR$644,19,FALSE),"") | C464: =IFERROR(VLOOKUP(F464,'Location List'!$A$2:$QR$644,18,FALSE),"") | D464: =IFERROR(VLOOKUP(F464,'Location List'!$A$2:$QR$644,9,FALSE),"") | E464: =IFERROR(VLOOKUP(F464,'Location List'!$A$2:$QR$644,2,FALSE),"")
A465: =IFERROR(VLOOKUP(F465,'Location List'!$A$2:$QR$463,20,FALSE),"") | B465: =IFERROR(VLOOKUP(F465,'Location List'!$A$2:$QR$644,19,FALSE),"") | C465: =IFERROR(VLOOKUP(F465,'Location List'!$A$2:$QR$644,18,FALSE),"") | D465: =IFERROR(VLOOKUP(F465,'Location List'!$A$2:$QR$644,9,FALSE),"") | E465: =IFERROR(VLOOKUP(F465,'Location List'!$A$2:$QR$644,2,FALSE),"")
A466: =IFERROR(VLOOKUP(F466,'Location List'!$A$2:$QR$463,20,FALSE),"") | B466: =IFERROR(VLOOKUP(F466,'Location List'!$A$2:$QR$644,19,FALSE),"") | C466: =IFERROR(VLOOKUP(F466,'Location List'!$A$2:$QR$644,18,FALSE),"") | D466: =IFERROR(VLOOKUP(F466,'Location List'!$A$2:$QR$644,9,FALSE),"") | E466: =IFERROR(VLOOKUP(F466,'Location List'!$A$2:$QR$644,2,FALSE),"")
A467: =IFERROR(VLOOKUP(F467,'Location List'!$A$2:$QR$463,20,FALSE),"") | B467: =IFERROR(VLOOKUP(F467,'Location List'!$A$2:$QR$644,19,FALSE),"") | C467: =IFERROR(VLOOKUP(F467,'Location List'!$A$2:$QR$644,18,FALSE),"") | D467: =IFERROR(VLOOKUP(F467,'Location List'!$A$2:$QR$644,9,FALSE),"") | E467: =IFERROR(VLOOKUP(F467,'Location List'!$A$2:$QR$644,2,FALSE),"")
A468: =IFERROR(VLOOKUP(F468,'Location List'!$A$2:$QR$463,20,FALSE),"") | B468: =IFERROR(VLOOKUP(F468,'Location List'!$A$2:$QR$644,19,FALSE),"") | C468: =IFERROR(VLOOKUP(F468,'Location List'!$A$2:$QR$644,18,FALSE),"") | D468: =IFERROR(VLOOKUP(F468,'Location List'!$A$2:$QR$644,9,FALSE),"") | E468: =IFERROR(VLOOKUP(F468,'Location List'!$A$2:$QR$644,2,FALSE),"")
A469: =IFERROR(VLOOKUP(F469,'Location List'!$A$2:$QR$463,20,FALSE),"") | B469: =IFERROR(VLOOKUP(F469,'Location List'!$A$2:$QR$644,19,FALSE),"") | C469: =IFERROR(VLOOKUP(F469,'Location List'!$A$2:$QR$644,18,FALSE),"") | D469: =IFERROR(VLOOKUP(F469,'Location List'!$A$2:$QR$644,9,FALSE),"") | E469: =IFERROR(VLOOKUP(F469,'Location List'!$A$2:$QR$644,2,FALSE),"")
A470: =IFERROR(VLOOKUP(F470,'Location List'!$A$2:$QR$463,20,FALSE),"") | B470: =IFERROR(VLOOKUP(F470,'Location List'!$A$2:$QR$644,19,FALSE),"") | C470: =IFERROR(VLOOKUP(F470,'Location List'!$A$2:$QR$644,18,FALSE),"") | D470: =IFERROR(VLOOKUP(F470,'Location List'!$A$2:$QR$644,9,FALSE),"") | E470: =IFERROR(VLOOKUP(F470,'Location List'!$A$2:$QR$644,2,FALSE),"")
A471: =IFERROR(VLOOKUP(F471,'Location List'!$A$2:$QR$463,20,FALSE),"") | B471: =IFERROR(VLOOKUP(F471,'Location List'!$A$2:$QR$644,19,FALSE),"") | C471: =IFERROR(VLOOKUP(F471,'Location List'!$A$2:$QR$644,18,FALSE),"") | D471: =IFERROR(VLOOKUP(F471,'Location List'!$A$2:$QR$644,9,FALSE),"") | E471: =IFERROR(VLOOKUP(F471,'Location List'!$A$2:$QR$644,2,FALSE),"")
A472: =IFERROR(VLOOKUP(F472,'Location List'!$A$2:$QR$463,20,FALSE),"") | B472: =IFERROR(VLOOKUP(F472,'Location List'!$A$2:$QR$644,19,FALSE),"") | C472: =IFERROR(VLOOKUP(F472,'Location List'!$A$2:$QR$644,18,FALSE),"") | D472: =IFERROR(VLOOKUP(F472,'Location List'!$A$2:$QR$644,9,FALSE),"") | E472: =IFERROR(VLOOKUP(F472,'Location List'!$A$2:$QR$644,2,FALSE),"")
A473: =IFERROR(VLOOKUP(F473,'Location List'!$A$2:$QR$463,20,FALSE),"") | B473: =IFERROR(VLOOKUP(F473,'Location List'!$A$2:$QR$644,19,FALSE),"") | C473: =IFERROR(VLOOKUP(F473,'Location List'!$A$2:$QR$644,18,FALSE),"") | D473: =IFERROR(VLOOKUP(F473,'Location List'!$A$2:$QR$644,9,FALSE),"") | E473: =IFERROR(VLOOKUP(F473,'Location List'!$A$2:$QR$644,2,FALSE),"")
A474: =IFERROR(VLOOKUP(F474,'Location List'!$A$2:$QR$463,20,FALSE),"") | B474: =IFERROR(VLOOKUP(F474,'Location List'!$A$2:$QR$644,19,FALSE),"") | C474: =IFERROR(VLOOKUP(F474,'Location List'!$A$2:$QR$644,18,FALSE),"") | D474: =IFERROR(VLOOKUP(F474,'Location List'!$A$2:$QR$644,9,FALSE),"") | E474: =IFERROR(VLOOKUP(F474,'Location List'!$A$2:$QR$644,2,FALSE),"")
A475: =IFERROR(VLOOKUP(F475,'Location List'!$A$2:$QR$463,20,FALSE),"") | B475: =IFERROR(VLOOKUP(F475,'Location List'!$A$2:$QR$644,19,FALSE),"") | C475: =IFERROR(VLOOKUP(F475,'Location List'!$A$2:$QR$644,18,FALSE),"") | D475: =IFERROR(VLOOKUP(F475,'Location List'!$A$2:$QR$644,9,FALSE),"") | E475: =IFERROR(VLOOKUP(F475,'Location List'!$A$2:$QR$644,2,FALSE),"")

Sheet Rolling 3 weeks
A2: Region | B2: RT | C2: DT | D2: DM | E2: Site name | F2: Site Code | G2: 3 weeks average | H2: =I2-7 -> 45950 | I2: =J2-7 -> 45957 | J2: 45964 | K2: Notes
A3: =IFERROR(VLOOKUP(F3,'Location List'!$A$2:$T$463,20,FALSE),"") -> Bill Eich | B3: =IFERROR(VLOOKUP(F3,'Location List'!$A$2:$T$644,19,FALSE),"") -> David Garcia | C3: =IFERROR(VLOOKUP(F3,'Location List'!$A$2:$T$644,18,FALSE),"") -> David Garibay Jr | D3: =IFERROR(VLOOKUP(F3,'Location List'!$A$2:$T$644,9,FALSE),"") -> ANTHONY CHAPA | E3: =IFERROR(VLOOKUP(F3,'Location List'!$A$2:$T$644,2,FALSE),"") -> TYLER | F3: 31 | G3: =AVERAGE(H3:JH3) -> 3.22 | H3: 3.29 | I3: 3.1 | J3: 3.27
A4: =IFERROR(VLOOKUP(F4,'Location List'!$A$2:$T$463,20,FALSE),"") -> Bill Eich | B4: =IFERROR(VLOOKUP(F4,'Location List'!$A$2:$T$644,19,FALSE),"") -> David Garcia | C4: =IFERROR(VLOOKUP(F4,'Location List'!$A$2:$T$644,18,FALSE),"") -> Hoang Dao | D4: =IFERROR(VLOOKUP(F4,'Location List'!$A$2:$T$644,9,FALSE),"") -> FRANK RAMIREZ | E4: =IFERROR(VLOOKUP(F4,'Location List'!$A$2:$T$644,2,FALSE),"") -> FM 1960 | F4: 32 | G4: =AVERAGE(H4:JH4) -> 3.03 | H4: 3.07 | I4: 3.1 | J4: 2.92
A5: =IFERROR(VLOOKUP(F5,'Location List'!$A$2:$T$463,20,FALSE),"") -> Bill Eich | B5: =IFERROR(VLOOKUP(F5,'Location List'!$A$2:$T$644,19,FALSE),"") -> David Garcia | C5: =IFERROR(VLOOKUP(F5,'Location List'!$A$2:$T$644,18,FALSE),"") -> Hoang Dao | D5: =IFERROR(VLOOKUP(F5,'Location List'!$A$2:$T$644,9,FALSE),"") -> FRANK RAMIREZ | E5: =IFERROR(VLOOKUP(F5,'Location List'!$A$2:$T$644,2,FALSE),"") -> COPPERFIELD | F5: 33 | G5: =AVERAGE(H5:JH5) -> 2.9233333 | H5: 2.99 | I5: 2.92 | J5: 2.86
A6: =IFERROR(VLOOKUP(F6,'Location List'!$A$2:$T$463,20,FALSE),"") -> Bill Eich | B6: =IFERROR(VLOOKUP(F6,'Location List'!$A$2:$T$644,19,FALSE),"") -> David Garcia | C6: =IFERROR(VLOOKUP(F6,'Location List'!$A$2:$T$644,18,FALSE),"") -> Mike Kralick | D6: =IFERROR(VLOOKUP(F6,'Location List'!$A$2:$T$644,9,FALSE),"") -> KELLI KASPER | E6: =IFERROR(VLOOKUP(F6,'Location List'!$A$2:$T$644,2,FALSE),"") -> LEWISVILLE | F6: 35 | G6: =AVERAGE(H6:JH6) -> 3.03 | H6: 2.93 | I6: 3 | J6: 3.16
A7: =IFERROR(VLOOKUP(F7,'Location List'!$A$2:$T$463,20,FALSE),"") -> Bill Eich | B7: =IFERROR(VLOOKUP(F7,'Location List'!$A$2:$T$644,19,FALSE),"") -> David Garcia | C7: =IFERROR(VLOOKUP(F7,'Location List'!$A$2:$T$644,18,FALSE),"") -> Jose Sandoval | D7: =IFERROR(VLOOKUP(F7,'Location List'!$A$2:$T$644,9,FALSE),"") -> ERIC BARGAS | E7: =IFERROR(VLOOKUP(F7,'Location List'!$A$2:$T$644,2,FALSE),"") -> ROCKWALL | F7: 38 | G7: =AVERAGE(H7:JH7) -> 2.9233333 | H7: 2.8 | I7: 2.91 | J7: 3.06
A8: =IFERROR(VLOOKUP(F8,'Location List'!$A$2:$T$463,20,FALSE),"") -> Bill Eich | B8: =IFERROR(VLOOKUP(F8,'Location List'!$A$2:$T$644,19,FALSE),"") -> Dennis Morgan | C8: =IFERROR(VLOOKUP(F8,'Location List'!$A$2:$T$644,18,FALSE),"") -> Wayne Rough | D8: =IFERROR(VLOOKUP(F8,'Location List'!$A$2:$T$644,9,FALSE),"") -> HASHEM SAADAT | E8: =IFERROR(VLOOKUP(F8,'Location List'!$A$2:$T$644,2,FALSE),"") -> ALBEMARLE | F8: 39 | G8: =AVERAGE(H8:JH8) -> 3.07 | H8: 3.02 | I8: 3.17 | J8: 3.02
A9: =IFERROR(VLOOKUP(F9,'Location List'!$A$2:$T$463,20,FALSE),"") -> Tim Kerum | B9: =IFERROR(VLOOKUP(F9,'Location List'!$A$2:$T$644,19,FALSE),"") -> Troy Chaney | C9: =IFERROR(VLOOKUP(F9,'Location List'!$A$2:$T$644,18,FALSE),"") -> Manuel Lopez | D9: =IFERROR(VLOOKUP(F9,'Location List'!$A$2:$T$644,9,FALSE),"") -> OCTAVIO CASTANEDA | E9: =IFERROR(VLOOKUP(F9,'Location List'!$A$2:$T$644,2,FALSE),"") -> BAKERSFIELD | F9: 41 | G9: =AVERAGE(H9:JH9) -> 3.05 | H9: 3.12 | I9: 3.08 | J9: 2.95
A10: =IFERROR(VLOOKUP(F10,'Location List'!$A$2:$T$463,20,FALSE),"") -> Tim Kerum | B10: =IFERROR(VLOOKUP(F10,'Location List'!$A$2:$T$644,19,FALSE),"") -> Troy Chaney | C10: =IFERROR(VLOOKUP(F10,'Location List'!$A$2:$T$644,18,FALSE),"") -> Albino Ramirez | D10: =IFERROR(VLOOKUP(F10,'Location List'!$A$2:$T$644,9,FALSE),"") -> Adam Shafran | E10: =IFERROR(VLOOKUP(F10,'Location List'!$A$2:$T$644,2,FALSE),"") -> FRESNO | F10: 42 | G10: =AVERAGE(H10:JH10) -> 2.91 | H10: 2.87 | I10: 3.01 | J10: 2.85
A11: =IFERROR(VLOOKUP(F11,'Location List'!$A$2:$T$463,20,FALSE),"") -> Tim Kerum | B11: =IFERROR(VLOOKUP(F11,'Location List'!$A$2:$T$644,19,FALSE),"") -> Troy Chaney | C11: =IFERROR(VLOOKUP(F11,'Location List'!$A$2:$T$644,18,FALSE),"") -> Manuel Lopez | D11: =IFERROR(VLOOKUP(F11,'Location List'!$A$2:$T$644,9,FALSE),"") -> OCTAVIO CASTANEDA | E11: =IFERROR(VLOOKUP(F11,'Location List'!$A$2:$T$644,2,FALSE),"") -> VISALIA | F11: 43 | G11: =AVERAGE(H11:JH11) -> 3.0233333 | H11: 3.07 | I11: 3.04 | J11: 2.96
A12: =IFERROR(VLOOKUP(F12,'Location List'!$A$2:$T$463,20,FALSE),"") -> Tim Kerum | B12: =IFERROR(VLOOKUP(F12,'Location List'!$A$2:$T$644,19,FALSE),"") -> Troy Chaney | C12: =IFERROR(VLOOKUP(F12,'Location List'!$A$2:$T$644,18,FALSE),"") | D12: =IFERROR(VLOOKUP(F12,'Location List'!$A$2:$T$644,9,FALSE),"") -> PATTY CEDILLO | E12: =IFERROR(VLOOKUP(F12,'Location List'!$A$2:$T$644,2,FALSE),"") -> OCEANSIDE | F12: 45 | G12: =AVERAGE(H12:JH12) -> 2.9666667 | H12: 3.01 | I12: 2.87 | J12: 3.02
A13: =IFERROR(VLOOKUP(F13,'Location List'!$A$2:$T$463,20,FALSE),"") -> Chris Kelly | B13: =IFERROR(VLOOKUP(F13,'Location List'!$A$2:$T$644,19,FALSE),"") -> Mike Seymour | C13: =IFERROR(VLOOKUP(F13,'Location List'!$A$2:$T$644,18,FALSE),"") -> James Schwab | D13: =IFERROR(VLOOKUP(F13,'Location List'!$A$2:$T$644,9,FALSE),"") -> REGINALD DAVENPORT | E13: =IFERROR(VLOOKUP(F13,'Location List'!$A$2:$T$644,2,FALSE),"") -> SPRINGFIELD (IL) | F13: 47 | G13: =AVERAGE(H13:JH13) -> 3.1 | H13: 3 | I13: 3.16 | J13: 3.14
A14: =IFERROR(VLOOKUP(F14,'Location List'!$A$2:$T$463,20,FALSE),"") -> Bill Eich | B14: =IFERROR(VLOOKUP(F14,'Location List'!$A$2:$T$644,19,FALSE),"") -> Dennis Morgan | C14: =IFERROR(VLOOKUP(F14,'Location List'!$A$2:$T$644,18,FALSE),"") -> Richard Boykin | D14: =IFERROR(VLOOKUP(F14,'Location List'!$A$2:$T$644,9,FALSE),"") -> BRIAN PITRE | E14: =IFERROR(VLOOKUP(F14,'Location List'!$A$2:$T$644,2,FALSE),"") -> ALEXANDRIA | F14: 48 | G14: =AVERAGE(H14:JH14) -> 2.99 | H14: 3.14 | I14: 2.92 | J14: 2.91
... A462: =IFERROR(VLOOKUP(F462,'Location List'!$A$2:$T$463,20,FALSE),"") -> Chris Kelly | B462: =IFERROR(VLOOKUP(F462,'Location List'!$A$2:$T$644,19,FALSE),"") -> Chris Parenti | C462: =IFERROR(VLOOKUP(F462,'Location List'!$A$2:$T$644,18,FALSE),"") -> Robert Lane | D462: =IFERROR(VLOOKUP(F462,'Location List'!$A$2:$T$644,9,FALSE),"") -> SUSAN JENSEN | E462: =IFERROR(VLOOKUP(F462,'Location List'!$A$2:$T$644,2,FALSE),"") -> ROANOKE | F462: 972 | G462: =AVERAGE(H462:JH462) -> 2.8833333 | H462: 2.89 | I462: 2.93 | J462: 2.83
A463: =IFERROR(VLOOKUP(F463,'Location List'!$A$2:$T$462,20,FALSE),"") | B463: =IFERROR(VLOOKUP(F463,'Location List'!$A$2:$T$644,19,FALSE),"") | C463: =IFERROR(VLOOKUP(F463,'Location List'!$A$2:$T$644,18,FALSE),"") | D463: =IFERROR(VLOOKUP(F463,'Location List'!$A$2:$T$644,9,FALSE),"") | E463: =IFERROR(VLOOKUP(F463,'Location List'!$A$2:$T$644,2,FALSE),"")
A464: =IFERROR(VLOOKUP(F464,'Location List'!$A$2:$T$462,20,FALSE),"") | B464: =IFERROR(VLOOKUP(F464,'Location List'!$A$2:$T$644,19,FALSE),"") | C464: =IFERROR(VLOOKUP(F464,'Location List'!$A$2:$T$644,18,FALSE),"") | D464: =IFERROR(VLOOKUP(F464,'Location List'!$A$2:$T$644,9,FALSE),"") | E464: =IFERROR(VLOOKUP(F464,'Location List'!$A$2:$T$644,2,FALSE),"")
A465: =IFERROR(VLOOKUP(F465,'Location List'!$A$2:$T$462,20,FALSE),"") | B465: =IFERROR(VLOOKUP(F465,'Location List'!$A$2:$T$644,19,FALSE),"") | C465: =IFERROR(VLOOKUP(F465,'Location List'!$A$2:$T$644,18,FALSE),"") | D465: =IFERROR(VLOOKUP(F465,'Location List'!$A$2:$T$644,9,FALSE),"") | E465: =IFERROR(VLOOKUP(F465,'Location List'!$A$2:$T$644,2,FALSE),"")
A466: =IFERROR(VLOOKUP(F466,'Location List'!$A$2:$T$462,20,FALSE),"") | B466: =IFERROR(VLOOKUP(F466,'Location List'!$A$2:$T$644,19,FALSE),"") | C466: =IFERROR(VLOOKUP(F466,'Location List'!$A$2:$T$644,18,FALSE),"") | D466: =IFERROR(VLOOKUP(F466,'Location List'!$A$2:$T$644,9,FALSE),"") | E466: =IFERROR(VLOOKUP(F466,'Location List'!$A$2:$T$644,2,FALSE),"")
A467: =IFERROR(VLOOKUP(F467,'Location List'!$A$2:$T$462,20,FALSE),"") | B467: =IFERROR(VLOOKUP(F467,'Location List'!$A$2:$T$644,19,FALSE),"") | C467: =IFERROR(VLOOKUP(F467,'Location List'!$A$2:$T$644,18,FALSE),"") | D467: =IFERROR(VLOOKUP(F467,'Location List'!$A$2:$T$644,9,FALSE),"") | E467: =IFERROR(VLOOKUP(F467,'Location List'!$A$2:$T$644,2,FALSE),"")
A468: =IFERROR(VLOOKUP(F468,'Location List'!$A$2:$T$462,20,FALSE),"") | B468: =IFERROR(VLOOKUP(F468,'Location List'!$A$2:$T$644,19,FALSE),"") | C468: =IFERROR(VLOOKUP(F468,'Location List'!$A$2:$T$644,18,FALSE),"") | D468: =IFERROR(VLOOKUP(F468,'Location List'!$A$2:$T$644,9,FALSE),"") | E468: =IFERROR(VLOOKUP(F468,'Location List'!$A$2:$T$644,2,FALSE),"")
A469: =IFERROR(VLOOKUP(F469,'Location List'!$A$2:$T$462,20,FALSE),"") | B469: =IFERROR(VLOOKUP(F469,'Location List'!$A$2:$T$644,19,FALSE),"") | C469: =IFERROR(VLOOKUP(F469,'Location List'!$A$2:$T$644,18,FALSE),"") | D469: =IFERROR(VLOOKUP(F469,'Location List'!$A$2:$T$644,9,FALSE),"") | E469: =IFERROR(VLOOKUP(F469,'Location List'!$A$2:$T$644,2,FALSE),"")
A470: =IFERROR(VLOOKUP(F470,'Location List'!$A$2:$T$462,20,FALSE),"") | B470: =IFERROR(VLOOKUP(F470,'Location List'!$A$2:$T$644,19,FALSE),"") | C470: =IFERROR(VLOOKUP(F470,'Location List'!$A$2:$T$644,18,FALSE),"") | D470: =IFERROR(VLOOKUP(F470,'Location List'!$A$2:$T$644,9,FALSE),"") | E470: =IFERROR(VLOOKUP(F470,'Location List'!$A$2:$T$644,2,FALSE),"")
A471: =IFERROR(VLOOKUP(F471,'Location List'!$A$2:$T$462,20,FALSE),"") | B471: =IFERROR(VLOOKUP(F471,'Location List'!$A$2:$T$644,19,FALSE),"") | C471: =IFERROR(VLOOKUP(F471,'Location List'!$A$2:$T$644,18,FALSE),"") | D471: =IFERROR(VLOOKUP(F471,'Location List'!$A$2:$T$644,9,FALSE),"") | E471: =IFERROR(VLOOKUP(F471,'Location List'!$A$2:$T$644,2,FALSE),"")
A472: =IFERROR(VLOOKUP(F472,'Location List'!$A$2:$T$462,20,FALSE),"") | B472: =IFERROR(VLOOKUP(F472,'Location List'!$A$2:$T$644,19,FALSE),"") | C472: =IFERROR(VLOOKUP(F472,'Location List'!$A$2:$T$644,18,FALSE),"") | D472: =IFERROR(VLOOKUP(F472,'Location List'!$A$2:$T$644,9,FALSE),"") | E472: =IFERROR(VLOOKUP(F472,'Location List'!$A$2:$T$644,2,FALSE),"")
A473: =IFERROR(VLOOKUP(F473,'Location List'!$A$2:$T$462,20,FALSE),"") | B473: =IFERROR(VLOOKUP(F473,'Location List'!$A$2:$T$644,19,FALSE),"") | C473: =IFERROR(VLOOKUP(F473,'Location List'!$A$2:$T$644,18,FALSE),"") | D473: =IFERROR(VLOOKUP(F473,'Location List'!$A$2:$T$644,9,FALSE),"") | E473: =IFERROR(VLOOKUP(F473,'Location List'!$A$2:$T$644,2,FALSE),"")
A474: =IFERROR(VLOOKUP(F474,'Location List'!$A$2:$T$462,20,FALSE),"") | B474: =IFERROR(VLOOKUP(F474,'Location List'!$A$2:$T$644,19,FALSE),"") | C474: =IFERROR(VLOOKUP(F474,'Location List'!$A$2:$T$644,18,FALSE),"") | D474: =IFERROR(VLOOKUP(F474,'Location List'!$A$2:$T$644,9,FALSE),"") | E474: =IFERROR(VLOOKUP(F474,'Location List'!$A$2:$T$644,2,FALSE),"")
... A477: =IFERROR(VLOOKUP(F477,'Location List'!$A$2:$T$462,20,FALSE),"") | B477: =IFERROR(VLOOKUP(F477,'Location List'!$A$2:$T$644,19,FALSE),"") | C477: =IFERROR(VLOOKUP(F477,'Location List'!$A$2:$T$644,18,FALSE),"") | D477: =IFERROR(VLOOKUP(F477,'Location List'!$A$2:$T$644,9,FALSE),"") | E477: =IFERROR(VLOOKUP(F477,'Location List'!$A$2:$T$644,2,FALSE),"")

Sheet Week to Week 
G3: Period 1 | L3: Period 2 | Q3: Period 3 | W3: Period 4 | AB3: Period 5 | AG3: Period 6 | AM3: Period 7 | AR3: Period 8 | AW3: Period 9 | BC3: Period 10 | BH3: Period 11 | BM3: Period 12
A4: Region | B4: RT | C4: DT | D4: DM | E4: Site name | F4: Site Code | G4: 45663 | H4: =SUM(G4+7) -> 45670 | I4: =SUM(H4+7) -> 45677 | J4: =SUM(I4+7) -> 45684 | K4: Pd 1 | L4: =SUM(J4+7) -> 45691 | M4: =SUM(L4+7) -> 45698 | N4: =SUM(M4+7) -> 45705 | O4: =SUM(N4+7) -> 45712 | P4: Pd 2 | Q4: =SUM(O4+7) -> 45719 | R4: =SUM(Q4+7) -> 45726 | S4: =SUM(R4+7) -> 45733 | T4: =SUM(S4+7) -> 45740 | U4: =SUM(T4+7) -> 45747 | V4: Pd 3 | W4: =SUM(U4+7) -> 45754 | X4: =SUM(W4+7) -> 45761 | Y4: =SUM(X4+7) -> 45768 | Z4: =SUM(Y4+7) -> 45775 | AA4: Pd 4 | AB4: =SUM(Z4+7) -> 45782 | AC4: =SUM(AB4+7) -> 45789 | AD4: =SUM(AC4+7) -> 45796 | AE4: =SUM(AD4+7) -> 45803 | AF4: Pd 5 | AG4: =SUM(AE4+7) -> 45810 | AH4: =SUM(AG4+7) -> 45817 | AI4: =SUM(AH4+7) -> 45824 | AJ4: =SUM(AI4+7) -> 45831 | AK4: =SUM(AJ4+7) -> 45838 | AL4: Pd 6 | AM4: =SUM(AK4+7) -> 45845 | AN4: =SUM(AM4+7) -> 45852 | AO4: =SUM(AN4+7) -> 45859 | AP4: =SUM(AO4+7) -> 45866 | AQ4: Pd 7 | AR4: =SUM(AP4+7) -> 45873 | AS4: =SUM(AR4+7) -> 45880 | AT4: =SUM(AS4+7) -> 45887 | AU4: =SUM(AT4+7) -> 45894 | AV4: Pd 8 | AW4: =SUM(AU4+7) -> 45901 | AX4: =SUM(AW4+7) -> 45908 | AY4: =SUM(AX4+7) -> 45915 | AZ4: =SUM(AY4+7) -> 45922 | BA4: =SUM(AZ4+7) -> 45929 | BB4: Pd 9 | BC4: =BA4+7 -> 45936 | BD4: =SUM(BC4+7) -> 45943 | BE4: =SUM(BD4+7) -> 45950 | BF4: =SUM(BE4+7) -> 45957 | BG4: Pd 10 | BH4: =SUM(BF4+7) -> 45964 | BI4: =SUM(BH4+7) -> 45971 | BJ4: =SUM(BI4+7) -> 45978 | BK4: =SUM(BJ4+7) -> 45985 | BL4: Pd 11 | BM4: =SUM(BK4+7) -> 45992 | BN4: =SUM(BM4+7) -> 45999 | BO4: =SUM(BN4+7) -> 46006 | BP4: =SUM(BO4+7) -> 46013 | BQ4: =SUM(BP4+7) -> 46020 | BR4: Pd 12
A5: =VLOOKUP(F5,'Location List'!$A$2:$T$644,20,FALSE) -> Bill Eich | B5: =VLOOKUP(F5,'Location List'!$A$2:$T$644,19,FALSE) -> David Garcia | C5: =VLOOKUP(F5,'Location List'!$A$2:$T$644,18,FALSE) -> David Garibay Jr | D5: =VLOOKUP(F5,'Location List'!$A$2:$T$644,9,FALSE) -> ANTHONY CHAPA | E5: =VLOOKUP(F5,'Location List'!$A$2:$T$644,2,FALSE) -> TYLER | F5: 31 | G5: 2.98 | H5: 3.13 | I5: 3.17 | J5: 3.02 | K5: =AVERAGE(G5:J5) -> 3.075 | L5: 3 | M5: 3.04 | N5: 3.17 | O5: 3.28 | P5: =AVERAGE(L5:O5) -> 3.1225 | Q5: 3.06 | R5: 3.18 | T5: 3.16 | U5: 3 | V5: =AVERAGE(Q5:U5) -> 3.1 | W5: 2.99 | X5: 3.02 | Y5: 3.15 | Z5: 2.93 | AA5: =AVERAGE(W5:Z5) -> 3.0225 | AB5: 3.04 | AC5: 3.11 | AD5: 3.11 | AE5: 3.19 | AF5: =AVERAGE(AB5:AE5) -> 3.1125 | AG5: 3.22 | AH5: 3.06 | AI5: 3.31 | AJ5: 3.11 | AK5: 2.89 | AL5: =AVERAGE(AH5:AK5) -> 3.0925 | AM5: 2.95 | AN5: 2.99 | AO5: 3.06 | AP5: 3.17 | AQ5: =AVERAGE(AM5:AP5) -> 3.0425 | AR5: 3.13 | AS5: 3.43 | AT5: 3.43 | AU5: 3.12 | AV5: =AVERAGE(AR5:AU5) -> 3.2775 | AW5: 3.13 | AX5: 2.9 | AY5: 3.15 | AZ5: 3.05 | BA5: 3.22 | BB5: =AVERAGE(AW5:BA5) -> 3.09 | BC5: 3.17 | BD5: 2.96 | BE5: 3.29 | BF5: 3.1 | BG5: =AVERAGE(BC5:BF5) -> 3.13 | BH5: 3.27 | BL5: =AVERAGE(BH5:BK5) -> 3.27 | BR5: =AVERAGE(BM5:BQ5) -> #DIV/0!
A6: =VLOOKUP(F6,'Location List'!$A$2:$T$644,20,FALSE) -> Bill Eich | B6: =VLOOKUP(F6,'Location List'!$A$2:$T$644,19,FALSE) -> David Garcia | C6: =VLOOKUP(F6,'Location List'!$A$2:$T$644,18,FALSE) -> Hoang Dao | D6: =VLOOKUP(F6,'Location List'!$A$2:$T$644,9,FALSE) -> FRANK RAMIREZ | E6: =VLOOKUP(F6,'Location List'!$A$2:$T$644,2,FALSE) -> FM 1960 | F6: 32 | G6: 3.09 | H6: 3.24 | I6: 3.36 | J6: 3.3 | K6: =AVERAGE(G6:J6) -> 3.2475 | L6: 3.49 | M6: 3.34 | N6: 3.26 | O6: 3.17 | P6: =AVERAGE(L6:O6) -> 3.315 | Q6: 3.35 | R6: 3.15 | T6: 3.63 | U6: 3.6 | V6: =AVERAGE(Q6:U6) -> 3.4325 | W6: 2.93 | X6: 3.07 | Y6: 3.03 | Z6: 3.15 | AA6: =AVERAGE(W6:Z6) -> 3.045 | AB6: 2.95 | AC6: 2.97 | AD6: 3.38 | AE6: 3.21 | AF6: =AVERAGE(AB6:AE6) -> 3.1275 | AG6: 3.02 | AH6: 2.85 | AI6: 2.96 | AJ6: 3.04 | AK6: 3.06 | AL6: =AVERAGE(AH6:AK6) -> 2.9775 | AM6: 3.23 | AN6: 3.31 | AO6: 3.18 | AP6: 3.16 | AQ6: =AVERAGE(AM6:AP6) -> 3.22 | AR6: 3.12 | AS6: 3.65 | AT6: 3.09 | AU6: 3.39 | AV6: =AVERAGE(AR6:AU6) -> 3.3125 | AW6: 2.99 | AX6: 2.92 | AY6: 2.96 | AZ6: 3.05 | BA6: 3.4 | BB6: =AVERAGE(AW6:BA6) -> 3.064 | BC6: 3.01 | BD6: 2.93 | BE6: 3.07 | BF6: 3.1 | BG6: =AVERAGE(BC6:BF6) -> 3.0275 | BH6: 2.92 | BL6: =AVERAGE(BH6:BK6) -> 2.92 | BR6: =AVERAGE(BM6:BQ6) -> #DIV/0!
A7: =VLOOKUP(F7,'Location List'!$A$2:$T$644,20,FALSE) -> Bill Eich | B7: =VLOOKUP(F7,'Location List'!$A$2:$T$644,19,FALSE) -> David Garcia | C7: =VLOOKUP(F7,'Location List'!$A$2:$T$644,18,FALSE) -> Hoang Dao | D7: =VLOOKUP(F7,'Location List'!$A$2:$T$644,9,FALSE) -> FRANK RAMIREZ | E7: =VLOOKUP(F7,'Location List'!$A$2:$T$644,2,FALSE) -> COPPERFIELD | F7: 33 | G7: 3.12 | H7: 3.07 | I7: 2.76 | J7: 3.15 | K7: =AVERAGE(G7:J7) -> 3.025 | L7: 3.19 | M7: 2.94 | N7: 2.95 | O7: 2.92 | P7: =AVERAGE(L7:O7) -> 3 | Q7: 2.87 | R7: 2.88 | T7: 3.3 | U7: 3.06 | V7: =AVERAGE(Q7:U7) -> 3.0275 | W7: 3.04 | X7: 2.96 | Y7: 3.01 | Z7: 3.19 | AA7: =AVERAGE(W7:Z7) -> 3.05 | AB7: 2.92 | AC7: 2.84 | AD7: 2.95 | AE7: 3.02 | AF7: =AVERAGE(AB7:AE7) -> 2.9325 | AG7: 3.04 | AH7: 3.3 | AI7: 3.05 | AJ7: 3.11 | AK7: 3.13 | AL7: =AVERAGE(AH7:AK7) -> 3.1475 | AM7: 3.13 | AN7: 2.88 | AO7: 3.1 | AP7: 2.91 | AQ7: =AVERAGE(AM7:AP7) -> 3.005 | AR7: 3 | AS7: 3.09 | AT7: 3.09 | AU7: 3.12 | AV7: =AVERAGE(AR7:AU7) -> 3.075 | AW7: 2.79 | AX7: 3 | AY7: 3.2 | AZ7: 2.98 | BA7: 3 | BB7: =AVERAGE(AW7:BA7) -> 2.994 | BC7: 2.73 | BD7: 3 | BE7: 2.99 | BF7: 2.92 | BG7: =AVERAGE(BC7:BF7) -> 2.91 | BH7: 2.86 | BL7: =AVERAGE(BH7:BK7) -> 2.86 | BR7: =AVERAGE(BM7:BQ7) -> #DIV/0!
A8: =VLOOKUP(F8,'Location List'!$A$2:$T$644,20,FALSE) -> Bill Eich | B8: =VLOOKUP(F8,'Location List'!$A$2:$T$644,19,FALSE) -> David Garcia | C8: =VLOOKUP(F8,'Location List'!$A$2:$T$644,18,FALSE) -> Mike Kralick | D8: =VLOOKUP(F8,'Location List'!$A$2:$T$644,9,FALSE) -> KELLI KASPER | E8: =VLOOKUP(F8,'Location List'!$A$2:$T$644,2,FALSE) -> LEWISVILLE | F8: 35 | G8: 3.2 | H8: 2.96 | I8: 3.01 | J8: 3.22 | K8: =AVERAGE(G8:J8) -> 3.0975 | L8: 3.04 | M8: 3.06 | N8: 3.21 | O8: 3.14 | P8: =AVERAGE(L8:O8) -> 3.1125 | Q8: 3.14 | R8: 3.33 | T8: 3.08 | U8: 3.1 | V8: =AVERAGE(Q8:U8) -> 3.1625 | W8: 3.03 | X8: 3.2 | Y8: 3.23 | Z8: 3.07 | AA8: =AVERAGE(W8:Z8) -> 3.1325 | AB8: 3.55 | AC8: 3.05 | AD8: 3.06 | AE8: 3.12 | AF8: =AVERAGE(AB8:AE8) -> 3.195 | AG8: 3.33 | AH8: 3.1 | AI8: 3.09 | AJ8: 3.14 | AK8: 3.23 | AL8: =AVERAGE(AH8:AK8) -> 3.14 | AM8: 3.32 | AN8: 3.37 | AO8: 3.38 | AP8: 3.22 | AQ8: =AVERAGE(AM8:AP8) -> 3.3225 | AR8: 3.49 | AS8: 2.75 | AT8: 2.91 | AU8: 2.91 | AV8: =AVERAGE(AR8:AU8) -> 3.015 | AW8: 2.95 | AX8: 2.98 | AY8: 3.02 | AZ8: 3.18 | BA8: 3.26 | BB8: =AVERAGE(AW8:BA8) -> 3.078 | BC8: 2.96 | BD8: 2.92 | BE8: 2.93 | BF8: 3 | BG8: =AVERAGE(BC8:BF8) -> 2.9525 | BH8: 3.16 | BL8: =AVERAGE(BH8:BK8) -> 3.16 | BR8: =AVERAGE(BM8:BQ8) -> #DIV/0!
A9: =VLOOKUP(F9,'Location List'!$A$2:$T$644,20,FALSE) -> Bill Eich | B9: =VLOOKUP(F9,'Location List'!$A$2:$T$644,19,FALSE) -> David Garcia | C9: =VLOOKUP(F9,'Location List'!$A$2:$T$644,18,FALSE) -> Jose Sandoval | D9: =VLOOKUP(F9,'Location List'!$A$2:$T$644,9,FALSE) -> ERIC BARGAS | E9: =VLOOKUP(F9,'Location List'!$A$2:$T$644,2,FALSE) -> ROCKWALL | F9: 38 | G9: 3.03 | H9: 3.12 | I9: 2.93 | J9: 3.08 | K9: =AVERAGE(G9:J9) -> 3.04 | L9: 2.99 | M9: 3.23 | N9: 3.04 | O9: 2.99 | P9: =AVERAGE(L9:O9) -> 3.0625 | Q9: 3.13 | R9: 2.97 | T9: 3.06 | U9: 2.69 | V9: =AVERAGE(Q9:U9) -> 2.9625 | W9: 2.7 | X9: 2.91 | Y9: 2.98 | Z9: 2.97 | AA9: =AVERAGE(W9:Z9) -> 2.89 | AB9: 2.81 | AC9: 2.88 | AD9: 2.73 | AE9: 3.12 | AF9: =AVERAGE(AB9:AE9) -> 2.885 | AG9: 2.87 | AH9: 2.88 | AI9: 2.7 | AJ9: 2.74 | AK9: 2.74 | AL9: =AVERAGE(AH9:AK9) -> 2.765 | AM9: 2.97 | AN9: 2.88 | AO9: 2.86 | AP9: 2.94 | AQ9: =AVERAGE(AM9:AP9) -> 2.9125 | AR9: 2.96 | AS9: 2.81 | AT9: 2.91 | AU9: 2.97 | AV9: =AVERAGE(AR9:AU9) -> 2.9125 | AW9: 3.1 | AX9: 2.98 | AY9: 3.11 | AZ9: 2.71 | BA9: 2.86 | BB9: =AVERAGE(AW9:BA9) -> 2.952 | BC9: 2.76 | BD9: 2.85 | BE9: 2.8 | BF9: 2.91 | BG9: =AVERAGE(BC9:BF9) -> 2.83 | BH9: 3.06 | BL9: =AVERAGE(BH9:BK9) -> 3.06 | BR9: =AVERAGE(BM9:BQ9) -> #DIV/0!
A10: =VLOOKUP(F10,'Location List'!$A$2:$T$644,20,FALSE) -> Bill Eich | B10: =VLOOKUP(F10,'Location List'!$A$2:$T$644,19,FALSE) -> Dennis Morgan | C10: =VLOOKUP(F10,'Location List'!$A$2:$T$644,18,FALSE) -> Wayne Rough | D10: =VLOOKUP(F10,'Location List'!$A$2:$T$644,9,FALSE) -> HASHEM SAADAT | E10: =VLOOKUP(F10,'Location List'!$A$2:$T$644,2,FALSE) -> ALBEMARLE | F10: 39 | G10: 3.17 | H10: 2.81 | I10: 3.03 | J10: 3.03 | K10: =AVERAGE(G10:J10) -> 3.01 | L10: 2.85 | M10: 3.45 | N10: 3.05 | O10: 2.9 | P10: =AVERAGE(L10:O10) -> 3.0625 | Q10: 2.86 | R10: 2.97 | T10: 3.18 | U10: 3.01 | V10: =AVERAGE(Q10:U10) -> 3.005 | W10: 3.19 | X10: 3.59 | Y10: 3.19 | Z10: 2.89 | AA10: =AVERAGE(W10:Z10) -> 3.215 | AB10: 2.96 | AC10: 2.96 | AD10: 2.88 | AE10: 3.11 | AF10: =AVERAGE(AB10:AE10) -> 2.9775 | AG10: 3.16 | AH10: 2.99 | AI10: 3.2 | AJ10: 3.02 | AK10: 3.19 | AL10: =AVERAGE(AH10:AK10) -> 3.1 | AM10: 2.84 | AN10: 2.95 | AO10: 3.15 | AP10: 2.89 | AQ10: =AVERAGE(AM10:AP10) -> 2.9575 | AR10: 2.89 | AS10: 3.02 | AT10: 2.7 | AU10: 2.96 | AV10: =AVERAGE(AR10:AU10) -> 2.8925 | AW10: 2.78 | AX10: 3.02 | AY10: 3.36 | AZ10: 3.07 | BA10: 2.88 | BB10: =AVERAGE(AW10:BA10) -> 3.022 | BC10: 3.05 | BD10: 3.04 | BE10: 3.02 | BF10: 3.17 | BG10: =AVERAGE(BC10:BF10) -> 3.07 | BH10: 3.02 | BL10: =AVERAGE(BH10:BK10) -> 3.02 | BR10: =AVERAGE(BM10:BQ10) -> #DIV/0!
A11: =VLOOKUP(F11,'Location List'!$A$2:$T$644,20,FALSE) -> Tim Kerum | B11: =VLOOKUP(F11,'Location List'!$A$2:$T$644,19,FALSE) -> Troy Chaney | C11: =VLOOKUP(F11,'Location List'!$A$2:$T$644,18,FALSE) -> Manuel Lopez | D11: =VLOOKUP(F11,'Location List'!$A$2:$T$644,9,FALSE) -> OCTAVIO CASTANEDA | E11: =VLOOKUP(F11,'Location List'!$A$2:$T$644,2,FALSE) -> BAKERSFIELD | F11: 41 | G11: 3.09 | H11: 3.1 | I11: 3.05 | J11: 2.94 | K11: =AVERAGE(G11:J11) -> 3.045 | L11: 3.06 | M11: 3.16 | N11: 2.92 | O11: 2.97 | P11: =AVERAGE(L11:O11) -> 3.0275 | Q11: 2.91 | R11: 2.98 | T11: 3.25 | U11: 3.09 | V11: =AVERAGE(Q11:U11) -> 3.0575 | W11: 3.1 | X11: 2.97 | Y11: 3.12 | Z11: 2.95 | AA11: =AVERAGE(W11:Z11) -> 3.035 | AB11: 2.97 | AC11: 2.98 | AD11: 3.02 | AE11: 2.96 | AF11: =AVERAGE(AB11:AE11) -> 2.9825 | AG11: 3.03 | AH11: 3.15 | AI11: 3.26 | AJ11: 3.01 | AK11: 3.11 | AL11: =AVERAGE(AH11:AK11) -> 3.1325 | AM11: 3.08 | AN11: 3.04 | AO11: 2.91 | AP11: 3.31 | AQ11: =AVERAGE(AM11:AP11) -> 3.085 | AR11: 2.84 | AS11: 2.96 | AT11: 2.95 | AU11: 2.87 | AV11: =AVERAGE(AR11:AU11) -> 2.905 | AW11: 2.93 | AX11: 2.9 | AY11: 2.96 | AZ11: 2.92 | BA11: 3.05 | BB11: =AVERAGE(AW11:BA11) -> 2.952 | BC11: 2.93 | BD11: 2.99 | BE11: 3.12 | BF11: 3.08 | BG11: =AVERAGE(BC11:BF11) -> 3.03 | BH11: 2.95 | BL11: =AVERAGE(BH11:BK11) -> 2.95 | BR11: =AVERAGE(BM11:BQ11) -> #DIV/0!
A12: =VLOOKUP(F12,'Location List'!$A$2:$T$644,20,FALSE) -> Tim Kerum | B12: =VLOOKUP(F12,'Location List'!$A$2:$T$644,19,FALSE) -> Troy Chaney | C12: =VLOOKUP(F12,'Location List'!$A$2:$T$644,18,FALSE) -> Albino Ramirez | D12: =VLOOKUP(F12,'Location List'!$A$2:$T$644,9,FALSE) -> Adam Shafran | E12: =VLOOKUP(F12,'Location List'!$A$2:$T$644,2,FALSE) -> FRESNO | F12: 42 | G12: 3.28 | H12: 3.09 | I12: 3.26 | J12: 3.38 | K12: =AVERAGE(G12:J12) -> 3.2525 | L12: 3.31 | M12: 3.32 | N12: 3.23 | O12: 3.63 | P12: =AVERAGE(L12:O12) -> 3.3725 | Q12: 3.15 | R12: 3.08 | T12: 3.07 | U12: 3.32 | V12: =AVERAGE(Q12:U12) -> 3.155 | W12: 3.25 | X12: 3.11 | Y12: 3.12 | Z12: 3.16 | AA12: =AVERAGE(W12:Z12) -> 3.16 | AB12: 3.1 | AC12: 3.14 | AD12: 3.1 | AE12: 3.11 | AF12: =AVERAGE(AB12:AE12) -> 3.1125 | AG12: 3.02 | AH12: 3.02 | AI12: 3 | AJ12: 3.03 | AK12: 3.16 | AL12: =AVERAGE(AH12:AK12) -> 3.0525 | AM12: 2.98 | AN12: 3.12 | AO12: 3.2 | AP12: 3.29 | AQ12: =AVERAGE(AM12:AP12) -> 3.1475 | AR12: 3.08 | AS12: 3.1 | AT12: 3.09 | AU12: 3.02 | AV12: =AVERAGE(AR12:AU12) -> 3.0725 | AW12: 3 | AX12: 2.95 | AY12: 2.92 | AZ12: 2.93 | BA12: 2.96 | BB12: =AVERAGE(AW12:BA12) -> 2.952 | BC12: 2.9 | BD12: 3 | BE12: 2.87 | BF12: 3.01 | BG12: =AVERAGE(BC12:BF12) -> 2.945 | BH12: 2.85 | BL12: =AVERAGE(BH12:BK12) -> 2.85 | BR12: =AVERAGE(BM12:BQ12) -> #DIV/0!
A13: =VLOOKUP(F13,'Location List'!$A$2:$T$644,20,FALSE) -> Tim Kerum | B13: =VLOOKUP(F13,'Location List'!$A$2:$T$644,19,FALSE) -> Troy Chaney | C13: =VLOOKUP(F13,'Location List'!$A$2:$T$644,18,FALSE) -> Manuel Lopez | D13: =VLOOKUP(F13,'Location List'!$A$2:$T$644,9,FALSE) -> OCTAVIO CASTANEDA | E13: =VLOOKUP(F13,'Location List'!$A$2:$T$644,2,FALSE) -> VISALIA | F13: 43 | G13: 3.48 | H13: 3.23 | I13: 3.08 | J13: 3.26 | K13: =AVERAGE(G13:J13) -> 3.2625 | L13: 3.06 | M13: 3.19 | N13: 3.28 | O13: 3.06 | P13: =AVERAGE(L13:O13) -> 3.1475 | Q13: 2.86 | R13: 2.98 | T13: 3.01 | U13: 3.19 | V13: =AVERAGE(Q13:U13) -> 3.01 | W13: 3.72 | X13: 3.06 | Y13: 3.51 | Z13: 3.03 | AA13: =AVERAGE(W13:Z13) -> 3.33 | AB13: 3.4 | AC13: 3.26 | AD13: 2.69 | AE13: 3.23 | AF13: =AVERAGE(AB13:AE13) -> 3.145 | AG13: 3.36 | AH13: 3.06 | AI13: 3.3 | AJ13: 3.15 | AK13: 3.35 | AL13: =AVERAGE(AH13:AK13) -> 3.215 | AM13: 3.32 | AN13: 3.05 | AO13: 3.21 | AP13: 3.08 | AQ13: =AVERAGE(AM13:AP13) -> 3.165 | AR13: 3.07 | AS13: 3.28 | AT13: 3.11 | AU13: 2.97 | AV13: =AVERAGE(AR13:AU13) -> 3.1075 | AW13: 2.83 | AX13: 2.92 | AY13: 3.22 | AZ13: 2.93 | BA13: 3.34 | BB13: =AVERAGE(AW13:BA13) -> 3.048 | BC13: 3.2 | BD13: 2.83 | BE13: 3.07 | BF13: 3.04 | BG13: =AVERAGE(BC13:BF13) -> 3.035 | BH13: 2.96 | BL13: =AVERAGE(BH13:BK13) -> 2.96 | BR13: =AVERAGE(BM13:BQ13) -> #DIV/0!
A14: =VLOOKUP(F14,'Location List'!$A$2:$T$644,20,FALSE) -> Tim Kerum | B14: =VLOOKUP(F14,'Location List'!$A$2:$T$644,19,FALSE) -> Troy Chaney | C14: =VLOOKUP(F14,'Location List'!$A$2:$T$644,18,FALSE) | D14: =VLOOKUP(F14,'Location List'!$A$2:$T$644,9,FALSE) -> PATTY CEDILLO | E14: =VLOOKUP(F14,'Location List'!$A$2:$T$644,2,FALSE) -> OCEANSIDE | F14: 45 | G14: 3.24 | H14: 3.13 | I14: 3.03 | J14: 3.27 | K14: =AVERAGE(G14:J14) -> 3.1675 | L14: 2.77 | M14: 2.84 | N14: 3.01 | O14: 3.07 | P14: =AVERAGE(L14:O14) -> 2.9225 | Q14: 3.53 | R14: 2.9 | T14: 3.04 | U14: 2.92 | V14: =AVERAGE(Q14:U14) -> 3.0975 | W14: 3.51 | X14: 2.89 | Y14: 3.2 | Z14: 3.02 | AA14: =AVERAGE(W14:Z14) -> 3.155 | AB14: 2.87 | AC14: 2.97 | AD14: 2.82 | AE14: 2.74 | AF14: =AVERAGE(AB14:AE14) -> 2.85 | AG14: 3.29 | AH14: 2.88 | AI14: 2.89 | AJ14: 3.04 | AK14: 3.01 | AL14: =AVERAGE(AH14:AK14) -> 2.955 | AM14: 3.37 | AN14: 2.97 | AO14: 2.95 | AP14: 2.73 | AQ14: =AVERAGE(AM14:AP14) -> 3.005 | AR14: 3.01 | AS14: 3.01 | AT14: 3.05 | AU14: 2.91 | AV14: =AVERAGE(AR14:AU14) -> 2.995 | AW14: 2.89 | AX14: 2.96 | AY14: 2.83 | AZ14: 2.95 | BA14: 2.97 | BB14: =AVERAGE(AW14:BA14) -> 2.92 | BC14: 2.88 | BD14: 2.74 | BE14: 3.01 | BF14: 2.87 | BG14: =AVERAGE(BC14:BF14) -> 2.875 | BH14: 3.02 | BL14: =AVERAGE(BH14:BK14) -> 3.02 | BR14: =AVERAGE(BM14:BQ14) -> #DIV/0!
A15: =VLOOKUP(F15,'Location List'!$A$2:$T$644,20,FALSE) -> Chris Kelly | B15: =VLOOKUP(F15,'Location List'!$A$2:$T$644,19,FALSE) -> Mike Seymour | C15: =VLOOKUP(F15,'Location List'!$A$2:$T$644,18,FALSE) -> James Schwab | D15: =VLOOKUP(F15,'Location List'!$A$2:$T$644,9,FALSE) -> REGINALD DAVENPORT | E15: =VLOOKUP(F15,'Location List'!$A$2:$T$644,2,FALSE) -> SPRINGFIELD (IL) | F15: 47 | G15: 2.98 | H15: 3.05 | I15: 3.05 | J15: 3.17 | K15: =AVERAGE(G15:J15) -> 3.0625 | L15: 3.03 | M15: 3.02 | N15: 3.12 | O15: 3 | P15: =AVERAGE(L15:O15) -> 3.0425 | Q15: 2.94 | R15: 2.98 | T15: 2.91 | U15: 3.07 | V15: =AVERAGE(Q15:U15) -> 2.975 | W15: 2.94 | X15: 2.94 | Y15: 3.14 | Z15: 3.05 | AA15: =AVERAGE(W15:Z15) -> 3.0175 | AB15: 3.01 | AC15: 2.99 | AD15: 3.03 | AE15: 3.2 | AF15: =AVERAGE(AB15:AE15) -> 3.0575 | AG15: 3.15 | AH15: 3.11 | AI15: 3.07 | AJ15: 2.92 | AK15: 3.23 | AL15: =AVERAGE(AH15:AK15) -> 3.0825 | AM15: 3.04 | AN15: 3.02 | AO15: 3.09 | AP15: 3.04 | AQ15: =AVERAGE(AM15:AP15) -> 3.0475 | AR15: 2.98 | AS15: 3.18 | AT15: 3.03 | AU15: 3.08 | AV15: =AVERAGE(AR15:AU15) -> 3.0675 | AW15: 3.11 | AX15: 2.93 | AY15: 2.76 | AZ15: 2.68 | BA15: 2.98 | BB15: =AVERAGE(AW15:BA15) -> 2.892 | BC15: 2.93 | BD15: 2.96 | BE15: 3 | BF15: 3.16 | BG15: =AVERAGE(BC15:BF15) -> 3.0125 | BH15: 3.14 | BL15: =AVERAGE(BH15:BK15) -> 3.14 | BR15: =AVERAGE(BM15:BQ15) -> #DIV/0!
A16: =VLOOKUP(F16,'Location List'!$A$2:$T$644,20,FALSE) -> Bill Eich | B16: =VLOOKUP(F16,'Location List'!$A$2:$T$644,19,FALSE) -> Dennis Morgan | C16: =VLOOKUP(F16,'Location List'!$A$2:$T$644,18,FALSE) -> Richard Boykin | D16: =VLOOKUP(F16,'Location List'!$A$2:$T$644,9,FALSE) -> BRIAN PITRE | E16: =VLOOKUP(F16,'Location List'!$A$2:$T$644,2,FALSE) -> ALEXANDRIA | F16: 48 | G16: 2.92 | H16: 2.95 | I16: 2.94 | J16: 2.87 | K16: =AVERAGE(G16:J16) -> 2.92 | L16: 2.83 | M16: 3.06 | N16: 3.06 | O16: 2.93 | P16: =AVERAGE(L16:O16) -> 2.97 | Q16: 2.8 | R16: 3.08 | T16: 3.41 | U16: 3.12 | V16: =AVERAGE(Q16:U16) -> 3.1025 | W16: 3.05 | X16: 3.05 | Y16: 3.17 | Z16: 3.14 | AA16: =AVERAGE(W16:Z16) -> 3.1025 | AB16: 2.97 | AC16: 2.86 | AD16: 2.91 | AE16: 2.96 | AF16: =AVERAGE(AB16:AE16) -> 2.925 | AG16: 3.06 | AH16: 2.99 | AI16: 2.85 | AJ16: 2.82 | AK16: 3.17 | AL16: =AVERAGE(AH16:AK16) -> 2.9575 | AM16: 2.96 | AN16: 2.89 | AO16: 3.12 | AP16: 2.92 | AQ16: =AVERAGE(AM16:AP16) -> 2.9725 | AR16: 2.97 | AS16: 3.25 | AT16: 3.17 | AU16: 2.92 | AV16: =AVERAGE(AR16:AU16) -> 3.0775 | AW16: 3.12 | AX16: 2.97 | AY16: 3.03 | AZ16: 2.83 | BA16: 3.2 | BB16: =AVERAGE(AW16:BA16) -> 3.03 | BC16: 2.86 | BD16: 2.87 | BE16: 3.14 | BF16: 2.92 | BG16: =AVERAGE(BC16:BF16) -> 2.9475 | BH16: 2.91 | BL16: =AVERAGE(BH16:BK16) -> 2.91 | BR16: =AVERAGE(BM16:BQ16) -> #DIV/0!
... A376: =VLOOKUP(F376,'Location List'!$A$2:$T$644,20,FALSE) -> Chris Kelly | B376: =VLOOKUP(F376,'Location List'!$A$2:$T$644,19,FALSE) -> Mike Seymour | C376: =VLOOKUP(F376,'Location List'!$A$2:$T$644,18,FALSE) -> Scott Whitsel | D376: =VLOOKUP(F376,'Location List'!$A$2:$T$644,9,FALSE) -> MICHAEL SVOBODA | E376: =VLOOKUP(F376,'Location List'!$A$2:$T$644,2,FALSE) -> TOWNSON | F376: 775 | G376: 3.06 | H376: 2.91 | I376: 2.91 | J376: 3.01 | K376: =AVERAGE(G376:J376) -> 2.9725 | L376: 2.98 | M376: 3.08 | N376: 2.95 | O376: 2.88 | P376: =AVERAGE(L376:O376) -> 2.9725 | Q376: 2.85 | R376: 2.88 | T376: 2.91 | U376: 2.84 | V376: =AVERAGE(Q376:U376) -> 2.87 | W376: 2.9 | X376: 2.92 | Y376: 2.97 | Z376: 2.94 | AA376: =AVERAGE(W376:Z376) -> 2.9325 | AB376: 3 | AC376: 2.96 | AD376: 2.96 | AE376: 2.88 | AF376: =AVERAGE(AB376:AE376) -> 2.95 | AG376: 3.01 | AH376: 2.98 | AI376: 2.96 | AJ376: 3.08 | AK376: 3.06 | AL376: =AVERAGE(AH376:AK376) -> 3.02 | AM376: 3.22 | AN376: 4.19 | AO376: 4.56 | AP376: 3.58 | AQ376: =AVERAGE(AM376:AP376) -> 3.8875 | AR376: 3.08 | AS376: 3.2 | AT376: 3.43 | AU376: 3.28 | AV376: =AVERAGE(AR376:AU376) -> 3.2475 | AW376: 2.94 | AX376: 2.94 | AY376: 2.69 | AZ376: 2.82 | BA376: 3.06 | BB376: =AVERAGE(AW376:BA376) -> 2.89 | BC376: 2.9 | BD376: 2.9 | BE376: 2.92 | BF376: 2.89 | BG376: =AVERAGE(BC376:BF376) -> 2.9025 | BH376: 2.84 | BL376: =AVERAGE(BH376:BK376) -> 2.84 | BR376: =AVERAGE(BM376:BQ376) -> #DIV/0!
